<!-- ======================================================

		MODEL: Inverted Pendulum
		AUTHOR: Atabak Dehban
		Modifed from the following model

    ======================================================
	Model 		:: Beam Balance

	Mujoco		:: Advanced physics simulation engine
		Source		: www.roboti.us
		Version		: 1.31
		Released 	: 23Apr16

	Author		:: Vikash Kumar
		Contacts 	: kumar@roboti.us
		Last edits 	: 30Apr'16, 30Nov'15, 10Oct'15
    ======================================================

THIS SOFTWARE IS PROVIDED BY THE COPYRIGHT HOLDERS AND CONTRIBUTORS "AS IS"
AND ANY EXPRESS OR IMPLIED WARRANTIES, INCLUDING, BUT NOT LIMITED TO, THE
IMPLIED WARRANTIES OF MERCHANTABILITY AND FITNESS FOR A PARTICULAR PURPOSE
ARE DISCLAIMED. IN NO EVENT SHALL THE COPYRIGHT HOLDER OR CONTRIBUTORS BE
LIABLE FOR ANY DIRECT, INDIRECT, INCIDENTAL, SPECIAL, EXEMPLARY, OR
CONSEQUENTIAL DAMAGES (INCLUDING, BUT NOT LIMITED TO, PROCUREMENT OF
SUBSTITUTE GOODS OR SERVICES; LOSS OF USE, DATA, OR PROFITS; OR BUSINESS
INTERRUPTION) HOWEVER CAUSED AND ON ANY THEORY OF LIABILITY, WHETHER IN
CONTRACT, STRICT LIABILITY, OR TORT (INCLUDING NEGLIGENCE OR OTHERWISE)
ARISING IN ANY WAY OUT OF THE USE OF THIS SOFTWARE, EVEN IF ADVISED OF THE
POSSIBILITY OF SUCH DAMAGE.
-->


<mujoco model="inverted pendulum">
	<compiler	angle="radian"/>
			
	<option	timestep="0.001"
			iterations="20">
		<flag sensornoise="enable"/>
	</option>
	
	<default>
	<geom  rgba="0.45 0.6 0.6 1"/>
		<site type="sphere" size="0.02"/>
	</default>
	<worldbody>
	
		<light directional="true" cutoff="4" exponent="20" diffuse="1 1 1" specular="0 0 0" pos=".9 .3 2.5" dir="-.9 -.3 -2.5 "/>
	
		<!-- ======= Ground ======= -->
		<geom name="ground" type="plane" pos="0 0 0" size="5 5 5" rgba=" .25 .26 .25 1"/>
		<!-- <site name="rFix" pos="0 -.2 .005"/>
		<site name="lFix" pos="0 .2 .005"/> -->
			
		<!-- ======= Beam ======= --> 
		<body name="beam" pos="0 0 1.1">
			<!--density of the rod is ten times smaller than other objects (e.g. the ball) for a better point mass approximation-->
            <geom pos="0 0 0.9" type="capsule" size=".018 .3" euler="1.57 0 0"/>

			<body name = "left" pos="0 -0.15 0">
				<geom name="rod1" type="cylinder" pos="0 0 0.0" size=".018 .9" mass="9.66"/> <!--rod1 길이와 질량-->
				<joint name="pivot1" pos="0 0 0.9" axis="0 1 0" limited="false" damping=".05"/>
				<!-- <site name="rBeam" pos="0 -.2 -.1"/> -->
				<!-- <site name="lBeam" pos="0 .2 -.1"/> -->
				<body name="ballbody1" pos="0 0 -0.9">
					<geom name="ballgeom1" type="sphere" size=".03"/>
				</body>
			</body>

			<body name = "right" pos="0 0.15 0">
				<geom name="rod2" type="cylinder" pos="0 0 0.0" size=".018 .9" mass="9.66"/> <!--rod2 길이와 질량-->
				<joint name="pivot2" pos="0 0 0.9" axis="0 1 0" limited="false" damping=".05"/>
				<!-- <site name="rBeam" pos="0 -.2 -.1"/> -->
				<!-- <site name="lBeam" pos="0 .2 -.1"/> -->
				<body name="ballbody2" pos="0 0 -0.9">
					<geom name="ballgeom2" type="sphere" size=".03"/>
				</body>
			</body>
		</body>

	</worldbody>
	
	<actuator>
        <motor joint='pivot1' name='motor1' gear="60" forcelimited="true" forcerange="-10 10"/>
	 		<position name="position_1" joint="pivot1" kp="20" />
       		<velocity name="velocity_1" joint="pivot1" kv="20" />
			<!-- <control name="control_1" joint="pivot1" control_type="sin" amplitude="0.5" frequency="0.1"/>  -->
		
		<motor joint='pivot2' name='motor2' gear="60" forcelimited="true" forcerange="-10 10"/>	
	     	<position name="position_2" joint="pivot2" kp="20" />
        	<velocity name="velocity_2" joint="pivot2" kv="1" />  
	</actuator>

	<!-- <sensor>
		<jointpos name="encoder" joint="pivot" noise="0.001"/> 
	</sensor> -->

	<contact>
		<exclude body1="beam" body2="left"/> 
		<exclude body1="beam" body2="right"/>
	</contact>

</mujoco>


